<?xml version="1.0"?>
<robot xmlns:xacro="http://www.ros.org/wiki/xacro" name="my_robot">

    <material name="green">
        <color rgba="0.0 0.5 0.0 1.0"/>
    </material>

    <material name="grey">
        <color rgba="0.5 0.5 0.5 1.0"/>
    </material>

    <material name="blue">
        <color rgba="0.0 0.0 1.0 1.0"/>
    </material>


    <link name="base_footprint"/>

    <link name="base_link">
        <visual name="">
            <origin xyz="0.0 0.0 0.1" rpy="0.0 0.0 0.0"/>
            <geometry>
                <box size="0.6 0.4 0.2"/>
            </geometry>
            <material name="green"/>
        </visual>
    </link>

<joint name="base_joint" type="fixed">
    <parent link="base_footprint"/>
    <child link="base_link"/>
    <origin xyz="0.0 0.0 0.1" rpy="0.0 0.0 0.0"/>
</joint>

<link name="right_wheel_link">
    <visual name="">
        <origin xyz="0.0 0.0 0.0" rpy="1.57 0.0 0.0"/>
        <geometry>
            <cylinder radius="0.1" length="0.05"/>
        </geometry>
        <material name="blue" />
    </visual>
</link>

<joint name="base_right_wheel_joint" type="continuous">
    <origin xyz="-0.15 -0.225 0.0" rpy="3.14 0.0 0.0"/>
    <parent link="base_link"/>
    <child link="right_wheel_link"/>
    <axis xyz="0.0 1.0 0.0"/>
</joint>


<link name="left_wheel_link">
    <visual>
        <geometry>
            <cylinder radius="0.1" length="0.05"/>
        </geometry>
        <material name="grey"/>
        <origin xyz="0.0 0.0 0.0" rpy="1.57 0.0 0.0"/>
    </visual>
</link>

<joint name="base_left_wheel_joint" type="continuous">
    <origin xyz="-0.15 0.225 0.0" rpy="0.0 0.0 0.0"/>
    <parent link="base_link"/>
    <child link="left_wheel_link"/>
    <axis xyz="0.0 1.0 0.0"/>
</joint>


<link name="caster_wheel_link">
    <visual>
        <origin xyz="0.0 0.0 0.0" rpy="0.0 0.0 0.0"/>
        <geometry>
            <sphere radius="0.05"/>
        </geometry>
        <material name="grey"/>
    </visual>
</link>

<joint name="base_caster_joint" type="fixed">
    <origin xyz="0.2 0.0 -0.05" rpy="0.0 0.0 0.0"/>
    <parent link="base_link"/>
    <child link="caster_wheel_link"/>

</joint>
</robot>